<?xml version="1.0" ?>
<robot name="rmpbot01" xmlns:xacro="http://www.ros.org/wiki/xacro">

<xacro:include filename="$(find rmpbot01_description)/urdf/materials.xacro" />
<xacro:include filename="$(find rmpbot01_description)/urdf/rmpbot01.trans" />
<xacro:include filename="$(find rmpbot01_description)/urdf/rmpbot01.gazebo" />
<link name="base_link">
  <inertial>
    <origin xyz="0.0006838460087994497 2.5818769471054665e-17 0.025615984582858856" rpy="0 0 0"/>
    <mass value="2.7652492954482564"/>
    <inertia ixx="0.002294" iyy="0.004534" izz="0.006344" ixy="-0.0" iyz="0.0" ixz="-1.3e-05"/>
  </inertial>
  <visual>
    <origin xyz="0 0 0" rpy="0 0 0"/>
    <geometry>
      <mesh filename="package://rmpbot01_description/meshes/base_link.stl" scale="0.001 0.001 0.001"/>
    </geometry>
    <material name="silver"/>
  </visual>
  <collision>
    <origin xyz="0 0 0" rpy="0 0 0"/>
    <geometry>
      <mesh filename="package://rmpbot01_description/meshes/base_link.stl" scale="0.001 0.001 0.001"/>
    </geometry>
  </collision>
</link>

<link name="lidar_1">
  <inertial>
    <origin xyz="5.026061718855929e-18 0.0 0.0050000000000000044" rpy="0 0 0"/>
    <mass value="0.2219535209761188"/>
    <inertia ixx="5.2e-05" iyy="5.2e-05" izz="0.0001" ixy="0.0" iyz="0.0" ixz="-0.0"/>
  </inertial>
  <visual>
    <origin xyz="-0.0 -0.0 -0.0525" rpy="0 0 0"/>
    <geometry>
      <mesh filename="package://rmpbot01_description/meshes/lidar_1.stl" scale="0.001 0.001 0.001"/>
    </geometry>
    <material name="silver"/>
  </visual>
  <collision>
    <origin xyz="-0.0 -0.0 -0.0525" rpy="0 0 0"/>
    <geometry>
      <mesh filename="package://rmpbot01_description/meshes/lidar_1.stl" scale="0.001 0.001 0.001"/>
    </geometry>
  </collision>
</link>

<link name="right_wheel_1">
  <inertial>
    <origin xyz="-2.713801405818117e-14 -0.009999999999999981 -3.469446951953614e-18" rpy="0 0 0"/>
    <mass value="0.2373669599327933"/>
    <inertia ixx="3.9e-05" iyy="6.3e-05" izz="3.9e-05" ixy="-0.0" iyz="0.0" ixz="-0.0"/>
  </inertial>
  <visual>
    <origin xyz="0.035 0.06 -0.0225" rpy="0 0 0"/>
    <geometry>
      <mesh filename="package://rmpbot01_description/meshes/right_wheel_1.stl" scale="0.001 0.001 0.001"/>
    </geometry>
    <material name="silver"/>
  </visual>
  <collision>
    <origin xyz="0.035 0.06 -0.0225" rpy="0 0 0"/>
    <geometry>
      <mesh filename="package://rmpbot01_description/meshes/right_wheel_1.stl" scale="0.001 0.001 0.001"/>
    </geometry>
  </collision>
</link>

<link name="left_wheel_1">
  <inertial>
    <origin xyz="-2.713801405818117e-14 0.009999999999999981 -3.469446951953614e-18" rpy="0 0 0"/>
    <mass value="0.2373669599327933"/>
    <inertia ixx="3.9e-05" iyy="6.3e-05" izz="3.9e-05" ixy="0.0" iyz="-0.0" ixz="-0.0"/>
  </inertial>
  <visual>
    <origin xyz="0.035 -0.06 -0.0225" rpy="0 0 0"/>
    <geometry>
      <mesh filename="package://rmpbot01_description/meshes/left_wheel_1.stl" scale="0.001 0.001 0.001"/>
    </geometry>
    <material name="silver"/>
  </visual>
  <collision>
    <origin xyz="0.035 -0.06 -0.0225" rpy="0 0 0"/>
    <geometry>
      <mesh filename="package://rmpbot01_description/meshes/left_wheel_1.stl" scale="0.001 0.001 0.001"/>
    </geometry>
  </collision>
</link>

<link name="caster_1">
  <inertial>
    <origin xyz="-0.029999999999999978 2.2594731004659047e-17 -0.0045901960387913065" rpy="0 0 0"/>
    <mass value="0.04320069502262114"/>
    <inertia ixx="2e-06" iyy="2e-06" izz="4e-06" ixy="-0.0" iyz="-0.0" ixz="0.0"/>
  </inertial>
  <visual>
    <origin xyz="-0.075 -0.0 -0.0125" rpy="0 0 0"/>
    <geometry>
      <mesh filename="package://rmpbot01_description/meshes/caster_1.stl" scale="0.001 0.001 0.001"/>
    </geometry>
    <material name="silver"/>
  </visual>
  <collision>
    <origin xyz="-0.075 -0.0 -0.0125" rpy="0 0 0"/>
    <geometry>
      <mesh filename="package://rmpbot01_description/meshes/caster_1.stl" scale="0.001 0.001 0.001"/>
    </geometry>
  </collision>
</link>

<joint name="Rigid 1" type="fixed">
  <origin xyz="0.0 0.0 0.0525" rpy="0 0 0"/>
  <parent link="base_link"/>
  <child link="lidar_1"/>
</joint>

<joint name="Revolute 2" type="continuous">
  <origin xyz="-0.035 -0.06 0.0225" rpy="0 0 0"/>
  <parent link="base_link"/>
  <child link="right_wheel_1"/>
  <axis xyz="0.0 1.0 0.0"/>
</joint>

<joint name="Revolute 3" type="continuous">
  <origin xyz="-0.035 0.06 0.0225" rpy="0 0 0"/>
  <parent link="base_link"/>
  <child link="left_wheel_1"/>
  <axis xyz="0.0 1.0 0.0"/>
</joint>

<joint name="Rigid 4" type="fixed">
  <origin xyz="0.075 0.0 0.0125" rpy="0 0 0"/>
  <parent link="base_link"/>
  <child link="caster_1"/>
</joint>

</robot>
